<?xml version="1.0"?>
<robot name="robot_name" xmlns:xacro="http://ros.org/wiki/xacro">


    <xacro:include filename="properties.xacro" />

    <!-- Root Link -->
    <link name="base_footprint">
    </link>
    <link name="base_link">
    </link>
    <joint name="base_foot_to_base_link" type="fixed">
        <parent link="base_link"/>
        <child link="base_footprint"/>
        <origin xyz="0.0 0.0 0.0" rpy="0.0 0.0 0.0"/>
    </joint>


    <link name="base">
        <visual>
            <origin xyz="0.0 0.0 0" rpy="0.0 0.0 0.0" />
            <geometry>
                <mesh filename="file://$(find myrobot_description)/meshes/base.stl"
                    scale="${scale_stl}" />
            </geometry>
            <material name="grey" />
        </visual>
        <collision>
            <geometry>
                <box size="${base_length} ${base_width} ${base_height}" />
            </geometry>
        </collision>
        <inertial>
            <mass value="${base_mass}" />
            <origin xyz="0 0 0" rpy="0 0 0" />
            <inertia
                ixx="${base_mass * (base_width * base_width + base_height * base_height) / 12.0}"
                ixy="0.0"
                ixz="0.0"
                iyy="${base_mass * (base_length * base_length + base_height * base_height) / 12.0}"
                iyz="0.0"
                izz="${base_mass * (base_length * base_length + base_width * base_width) / 12.0}" />
        </inertial>
    </link>

    <!-- Wheel macro with correct cylindrical inertia -->
    <xacro:macro name="wheel_link" params="prefix">
        <link name="${prefix}_wheel">
            <visual>
                <origin xyz="0 0 0" rpy="0 0 0" />
                <geometry>
                    <!-- <mesh filename="package://myrobot_description/meshes/blue_tyre.stl"
                        scale="${scale_stl}" /> -->
                    <mesh filename="file://$(find myrobot_description)/meshes/blue_tyre.stl"
                        scale="${scale_stl}" />
                </geometry>
                <material name="black" />
            </visual>
            <collision>
                <origin rpy="0 0 0" xyz="0 0 0" />
                <geometry>
                    <!-- <cylinder radius="${wheel_radius}" length="${wheel_thickness}" /> -->
                    <mesh filename="file://$(find myrobot_description)/meshes/blue_tyre.stl"
                        scale="${scale_stl}" />
                </geometry>
            </collision>
            <inertial>
                <mass value="${wheel_mass}" />
                <origin xyz="0 0 0" rpy="0 0 0" />
                <inertia
                    ixx="${wheel_mass * (3 * wheel_radius * wheel_radius + wheel_thickness * wheel_thickness) / 12}"
                    ixy="0"
                    ixz="0"
                    iyy="${wheel_mass * wheel_radius * wheel_radius / 2}"
                    iyz="0"
                    izz="${wheel_mass * (3 * wheel_radius * wheel_radius + wheel_thickness * wheel_thickness) / 12}" />
            </inertial>
        </link>

        <gazebo reference="${prefix}_wheel">
            <material>Gazebo/Black</material>
            <mu1 value="0.7" />
            <mu2 value="0.7" />
        </gazebo>
    </xacro:macro>

    <!-- Use the wheel macro for all wheels -->
    <xacro:wheel_link prefix="front_right" />
    <xacro:wheel_link prefix="front_left" />
    <xacro:wheel_link prefix="rear_right" />
    <xacro:wheel_link prefix="rear_left" />

    <!-- Joints remain the same -->
    <joint name="base_link_to_base" type="fixed">
        <parent link="base_link" />
        <child link="base" />
        <origin xyz="0.0 0.0 ${wheel_radius}" rpy="0.0 0.0 0.0" />
    </joint>

    <joint name="front_right_wheel_joint" type="continuous">
        <origin xyz="${wheel_dist_x} -${wheel_dist_y} 0" rpy="0 0 0" />
        <parent link="base" />
        <child link="front_right_wheel" />
        <axis xyz="0 1 0" />
    </joint>

    <joint name="front_left_wheel_joint" type="continuous">
        <origin xyz="${wheel_dist_x} ${wheel_dist_y} 0" rpy="0 0 ${pie}" />
        <parent link="base" />
        <child link="front_left_wheel" />
        <axis xyz="0 -1 0" />
    </joint>

    <joint name="rear_right_wheel_joint" type="continuous">
        <origin xyz="-${wheel_dist_x} -${wheel_dist_y} 0" rpy="0 0 0" />
        <parent link="base" />
        <child link="rear_right_wheel" />
        <axis xyz="0 1 0" />
    </joint>

    <joint name="rear_left_wheel_joint" type="continuous">
        <origin xyz="-${wheel_dist_x} ${wheel_dist_y} 0" rpy="0 0 -${pie}" />
        <parent link="base" />
        <child link="rear_left_wheel" />
        <axis xyz="0 -1 0" />
    </joint>

    <!-- Lidar link -->
    <link name="laser">
        <visual>
            <origin rpy="0 0 0" xyz="0 0 0" />
            <geometry>
                <mesh filename="file://$(find myrobot_description)/meshes/mid_360.stl"
                    scale="${scale_stl}" />
            </geometry>
            <material name="blue" />
        </visual>
        <collision>
            <geometry>
                <cylinder radius="0.05" length="0.04" />
            </geometry>
        </collision>
        <inertial>
            <mass value="0.5" />
            <origin xyz="0 0 0" rpy="0 0 0" />
            <inertia
                ixx="0.0001" ixy="0" ixz="0"
                iyy="0.0001" iyz="0"
                izz="0.0001" />
        </inertial>
    </link>

    <joint name="laser_joint" type="fixed">
        <origin xyz="${lidar_dist_x} ${lidar_dist_y} ${lidar_dist_z}" rpy="0 0 0" />
        <parent link="base" />
        <child link="laser" />
    </joint>

    <xacro:include filename="laser.urdf.xacro" />

    <xacro:include filename="gazebo_control.xacro" />

    <xacro:include filename="imu.urdf.xacro" />

    <xacro:imu />

</robot>