<?xml version="1.0"?>
<robot name="robot_name" xmlns:xacro="http://ros.org/wiki/xacro">
    <!-- Materials remain the same -->
    <material name="blue">
        <color rgba="0 0 0.8 1" />
    </material>
    <material name="grey">
        <color rgba="0.9 0.95 0.95 1.0" />
    </material>
    <material name="black">
        <color rgba="0 0 0 1" />
    </material>
    <material name="green">
        <color rgba="0.0 0.8 0.0 1.0" />
    </material>

    <!-- Properties -->
    <xacro:property name="scale_stl" value="1 1 1" />
    <xacro:property name="wheel_dist_x" value="0.21" />
    <xacro:property name="wheel_dist_y" value="0.35" />
    <xacro:property name="lidar_dist_x" value="0.363" />
    <xacro:property name="lidar_dist_y" value="0" />
    <xacro:property name="lidar_dist_z" value="0.239" />
    <xacro:property name="pie" value="3.1415926" />

    <!-- Wheel properties -->
    <xacro:property name="wheel_radius" value="0.1" />
    <xacro:property name="wheel_thickness" value="0.05" />
    <xacro:property name="wheel_mass" value="1.0" />

    <!-- Base properties -->
    <xacro:property name="base_mass" value="15.0" />
    <xacro:property name="base_length" value="0.5" />
    <xacro:property name="base_width" value="0.3" />
    <xacro:property name="base_height" value="0.15" />

    <!-- Root Link -->
    <link name="base_link">
    </link>

    <link name="base">
        <visual>
            <origin xyz="0.0 0.0 0.0" rpy="0.0 0.0 0.0" />
            <geometry>
                <mesh filename="package://myrobot_description/stl/base.stl" scale="${scale_stl}" />
            </geometry>
            <material name="grey" />
        </visual>
        <collision>
            <geometry>
                <box size="${base_length} ${base_width} ${base_height}" />
            </geometry>
        </collision>
        <inertial>
            <mass value="${base_mass}" />
            <origin xyz="0 0 0" rpy="0 0 0" />
            <inertia
                ixx="${base_mass * (base_width * base_width + base_height * base_height) / 12.0}"
                ixy="0.0"
                ixz="0.0"
                iyy="${base_mass * (base_length * base_length + base_height * base_height) / 12.0}"
                iyz="0.0"
                izz="${base_mass * (base_length * base_length + base_width * base_width) / 12.0}" />
        </inertial>
    </link>

    <!-- Wheel macro with correct cylindrical inertia -->
    <xacro:macro name="wheel_link" params="prefix">
        <link name="${prefix}_wheel">
            <visual>
                <origin rpy="0 0 0" xyz="0 0 0" />
                <geometry>
                    <mesh filename="package://myrobot_description/stl/blue_tyre.stl"
                        scale="${scale_stl}" />
                </geometry>
                <material name="black" />
            </visual>
            <collision>
                <origin rpy="${pi/2} 0 0" xyz="0 0 0" /> 
                <geometry>
                    <cylinder radius="${wheel_radius}" length="${wheel_thickness}" />
                </geometry>
            </collision>
            <inertial>
                <mass value="${wheel_mass}" />
                <origin xyz="0 0 0" rpy="0 0 0" />
                <inertia
                    ixx="${wheel_mass * (3 * wheel_radius * wheel_radius + wheel_thickness * wheel_thickness) / 12}"
                    ixy="0"
                    ixz="0"
                    iyy="${wheel_mass * (3 * wheel_radius * wheel_radius + wheel_thickness * wheel_thickness) / 12}"
                    iyz="0"
                    izz="${wheel_mass * wheel_radius * wheel_radius / 2}" />
            </inertial>
        </link>

        <gazebo reference="${prefix}_wheel">
            <material>Gazebo/Black</material>
            <mu1 value="1.0" />
            <mu2 value="1.0" />
            <kp value="10000000.0" />
            <kd value="1.0" />
        </gazebo>
    </xacro:macro>

    <!-- Use the wheel macro for all wheels -->
    <xacro:wheel_link prefix="front_right" />
    <xacro:wheel_link prefix="front_left" />
    <xacro:wheel_link prefix="rear_right" />
    <xacro:wheel_link prefix="rear_left" />

    <!-- Joints remain the same -->
    <joint name="base_link_to_base" type="fixed">
        <parent link="base_link" />
        <child link="base" />
        <origin xyz="0.0 0.0 0.0" rpy="0.0 0.0 0.0" />
    </joint>

    <joint name="front_right_wheel_joint" type="continuous">
        <origin xyz="${wheel_dist_x} -${wheel_dist_y} 0" rpy="0 0 0" />
        <parent link="base" />
        <child link="front_right_wheel" />
        <axis xyz="0 1 0" />
    </joint>

    <joint name="front_left_wheel_joint" type="continuous">
        <origin xyz="${wheel_dist_x} ${wheel_dist_y} 0" rpy="0 0 ${pie}" />
        <parent link="base" />
        <child link="front_left_wheel" />
        <axis xyz="0 -1 0" />
    </joint>

    <joint name="rear_right_wheel_joint" type="continuous">
        <origin xyz="-${wheel_dist_x} -${wheel_dist_y} 0" rpy="0 0 0" />
        <parent link="base" />
        <child link="rear_right_wheel" />
        <axis xyz="0 1 0" />
    </joint>

    <joint name="rear_left_wheel_joint" type="continuous">
        <origin xyz="-${wheel_dist_x} ${wheel_dist_y} 0" rpy="0 0 -${pie}" />
        <parent link="base" />
        <child link="rear_left_wheel" />
        <axis xyz="0 -1 0" />
    </joint>

    <!-- Lidar link -->
    <link name="laser">
        <visual>
            <origin rpy="0 0 0" xyz="0 0 0" />
            <geometry>
                <mesh filename="package://myrobot_description/stl/mid_360.stl" scale="${scale_stl}" />
            </geometry>
            <material name="blue" />
        </visual>
        <collision>
            <geometry>
                <cylinder radius="0.05" length="0.04" />
            </geometry>
        </collision>
        <inertial>
            <mass value="0.5" />
            <origin xyz="0 0 0" rpy="0 0 0" />
            <inertia
                ixx="0.0001" ixy="0" ixz="0"
                iyy="0.0001" iyz="0"
                izz="0.0001" />
        </inertial>
    </link>

    <joint name="laser_joint" type="fixed">
        <origin xyz="${lidar_dist_x} ${lidar_dist_y} ${lidar_dist_z}" rpy="0 0 0" />
        <parent link="base" />
        <child link="laser" />
    </joint>

    <gazebo reference="laser">
        <material>Gazebo/Blue</material>
    </gazebo>

</robot>