<?xml version="1.0" ?>
<!-- =================================================================================== -->
<!-- |    This document was autogenerated by xacro from robot.urdf.xacro               | -->
<!-- |    EDITING THIS FILE BY HAND IS NOT RECOMMENDED                                 | -->
<!-- =================================================================================== -->
<robot name="robot_name">
  <material name="blue">
    <color rgba="0 0 0.8 1"/>
  </material>
  <material name="grey">
    <color rgba="0.9 0.95 0.95 1.0"/>
  </material>
  <material name="black">
    <color rgba="0 0 0 1"/>
  </material>
  <material name="green">
    <color rgba="0.0 0.8 0.0 1.0"/>
  </material>
  <!-- Root Link -->
  <link name="base_link">
    </link>
  <link name="base">
    <visual name="">
      <origin rpy="0.0 0.0 0.0" xyz="0.0 0.0 0.0"/>
      <geometry>
        <mesh filename="package://robot_description/stl/Base.stl" scale="0.001001 0.001001 0.001001"/>
      </geometry>
      <material name="grey"/>
    </visual>
    <collision>
      <geometry>
        <mesh filename="package://robot_description/stl/Base.stl" scale="0.001001 0.001001 0.001001"/>
      </geometry>
    </collision>
  </link>
  <!-- Joint to Connect Links -->
  <joint name="base_link_to_base" type="fixed">
    <parent link="base_link"/>
    <child link="base"/>
    <origin rpy="0.0 0.0 0.0" xyz="0.0 0.0 0.0"/>
  </joint>
  <joint name="front_right_wheel_joint" type="continuous">
    <origin rpy="0 0 0" xyz="0.21 -0.35 0"/>
    <parent link="base"/>
    <child link="front_right_wheel"/>
    <axis xyz="0 1 0"/>
  </joint>
  <link name="front_right_wheel">
    <visual>
      <origin rpy="0 0 0 " xyz="0 0 0"/>
      <geometry>
        <mesh filename="package://robot_description/stl/blue_tyre.stl" scale="0.001001 0.001001 0.001001"/>
      </geometry>
      <material name="black"/>
    </visual>
    <collision>
      <origin rpy="0 0 0" xyz="0 0 0 "/>
      <geometry>
        <mesh filename="package://robot_description/stl/blue_tyre.stl" scale="0.001001 0.001001 0.001001"/>
      </geometry>
    </collision>
  </link>
  <joint name="front_left_wheel_joint" type="continuous">
    <origin rpy="0 0 3.1415926" xyz="0.21 0.35 0"/>
    <parent link="base"/>
    <child link="front_left_wheel"/>
    <axis xyz="0 -1 0"/>
  </joint>
  <link name="front_left_wheel">
    <visual>
      <origin rpy="0 0 0 " xyz="0 0 0"/>
      <geometry>
        <mesh filename="package://robot_description/stl/blue_tyre.stl" scale="0.001001 0.001001 0.001001"/>
      </geometry>
      <material name="black"/>
    </visual>
    <collision>
      <origin rpy="0 0 0" xyz="0 0 0 "/>
      <geometry>
        <mesh filename="package://robot_description/stl/blue_tyre.stl" scale="0.001001 0.001001 0.001001"/>
      </geometry>
    </collision>
  </link>
  <joint name="rear_right_wheel_joint" type="continuous">
    <origin rpy="0 0 0" xyz="-0.21 -0.35 0"/>
    <parent link="base"/>
    <child link="rear_right_wheel"/>
    <axis xyz="0 1 0"/>
  </joint>
  <link name="rear_right_wheel">
    <visual>
      <origin rpy="0 0 0 " xyz="0 0 0"/>
      <geometry>
        <mesh filename="package://robot_description/stl/blue_tyre.stl" scale="0.001001 0.001001 0.001001"/>
      </geometry>
      <material name="black"/>
    </visual>
    <collision>
      <origin rpy="0 0 0" xyz="0 0 0 "/>
      <geometry>
        <mesh filename="package://robot_description/stl/blue_tyre.stl" scale="0.001001 0.001001 0.001001"/>
      </geometry>
    </collision>
  </link>
  <joint name="rear_left_wheel_joint" type="continuous">
    <origin rpy="0 0 -3.1415926" xyz="-0.21 0.35 0"/>
    <parent link="base"/>
    <child link="rear_left_wheel"/>
    <axis xyz="0 -1 0"/>
  </joint>
  <link name="rear_left_wheel">
    <visual>
      <origin rpy="0 0 0 " xyz="0 0 0"/>
      <geometry>
        <mesh filename="package://robot_description/stl/blue_tyre.stl" scale="0.001001 0.001001 0.001001"/>
      </geometry>
      <material name="black"/>
    </visual>
    <collision>
      <origin rpy="0 0 0" xyz="0 0 0 "/>
      <geometry>
        <mesh filename="package://robot_description/stl/blue_tyre.stl" scale="0.001001 0.001001 0.001001"/>
      </geometry>
    </collision>
  </link>
  <joint name="laser_joint" type="fixed">
    <origin rpy="0 0 0" xyz="0.363 0 0.239 "/>
    <parent link="base"/>
    <child link="laser"/>
  </joint>
  <link name="laser">
    <visual>
      <origin rpy="0 0 0" xyz="0 0 0 "/>
      <geometry>
        <mesh filename="package://robot_description/stl/mid_360.stl" scale="0.001001 0.001001 0.001001"/>
      </geometry>
      <material name="blue"/>
    </visual>
    <collision>
      <geometry>
        <mesh filename="package://robot_description/stl/mid_360.stl" scale="0.001001 0.001001 0.001001"/>
      </geometry>
    </collision>
  </link>
</robot>
