<?xml version="1.0" ?>
<!-- =================================================================================== -->
<!-- |    This document was autogenerated by xacro from claude_robot.urdf.xacro        | -->
<!-- |    EDITING THIS FILE BY HAND IS NOT RECOMMENDED                                 | -->
<!-- =================================================================================== -->
<robot name="test_robot">
  <!-- Single material -->
  <material name="grey">
    <color rgba="0.9 0.95 0.95 1.0"/>
  </material>
  <!-- Base link -->
  <link name="base_link">
    <inertial>
      <mass value="0.1"/>
      <origin rpy="0 0 0" xyz="0 0 0"/>
      <inertia ixx="0.001" ixy="0" ixz="0" iyy="0.001" iyz="0" izz="0.001"/>
    </inertial>
  </link>
  <!-- Base -->
  <link name="base">
    <visual>
      <origin rpy="0.0 0.0 0.0" xyz="0.0 0.0 0.0"/>
      <geometry>
        <box size="0.5 0.3 0.15"/>
      </geometry>
      <material name="grey"/>
    </visual>
    <collision>
      <geometry>
        <box size="0.5 0.3 0.15"/>
      </geometry>
    </collision>
    <inertial>
      <mass value="15.0"/>
      <origin rpy="0 0 0" xyz="0 0 0"/>
      <inertia ixx="0.2" ixy="0.0" ixz="0.0" iyy="0.2" iyz="0.0" izz="0.2"/>
    </inertial>
  </link>
  <!-- Single wheel -->
  <link name="front_right_wheel">
    <visual>
      <origin rpy="0 0 0" xyz="0 0 0"/>
      <geometry>
        <mesh filename="package://robot_description/stl/blue_tyre_scaled.stl" scale="1 1 1"/>
      </geometry>
      <!-- <geometry>
                <cylinder radius="0.1" length="0.05" />
            </geometry> -->
      <material name="grey"/>
    </visual>
    <collision>
      <geometry>
        <cylinder length="0.05" radius="0.1"/>
      </geometry>
    </collision>
    <inertial>
      <mass value="1.0"/>
      <origin rpy="0 0 0" xyz="0 0 0"/>
      <inertia ixx="0.001" ixy="0" ixz="0" iyy="0.001" iyz="0" izz="0.001"/>
    </inertial>
  </link>
  <!-- Basic joints -->
  <joint name="base_link_to_base" type="fixed">
    <parent link="base_link"/>
    <child link="base"/>
    <origin rpy="0 0 0" xyz="0 0 0"/>
  </joint>
  <joint name="front_right_wheel_joint" type="continuous">
    <origin rpy="0 0 0" xyz="0.21 -0.35 0"/>
    <parent link="base"/>
    <child link="front_right_wheel"/>
    <axis xyz="0 1 0"/>
  </joint>
</robot>
